<?xml version="1.0"?>
<robot xmlns:xacro="http://www.ros.org/wiki/xacro">
    <xacro:macro name="wheel" params="prefix reflect">
        <link name="${prefix}_wheel">
            <visual>
                <geometry>
                    <cylinder length="0.1" radius="0.2"/>
                </geometry>
                <origin xyz="0 0 0" rpy="${reflect*1.570796} 0 0"/>
                <material name="black">
                    <color rgba="0.05 0.05 0.05 1.0"/>
                </material>
            </visual>
            <collision >
                <origin xyz="0 0 0" rpy="1.570795 0 0" />
                <geometry >
                    <cylinder length ="0.1" radius ="0.2" />
                </geometry >
            </collision >
            <inertial >
                <origin xyz="0 0 0" rpy="1.570795 0 0" />
                <mass value="1"/>
                <inertia
                    ixx="0.010833333" ixy="0" ixz="0"
                    iyy="0.010833333" iyz="0"
                    izz="0.005" />
            </inertial >
        </link>
        <joint name="${prefix}_wheel_joint" type="continuous">
            <parent link="base_link"/>
            <child link="${prefix}_wheel"/>
            <origin xyz="0 ${reflect*-0.3} 0" rpy="0 0 0"/>
            <axis xyz="0 1 0"/>
        </joint>
        <gazebo reference="${prefix}_wheel">
            <mu1>1.0</mu1>
            <mu2>1.0</mu2>
            <kp>500000.0</kp>
            <kd>10.0</kd>
            <minDepth>0.001</minDepth>
            <maxVel>0.1</maxVel>
            <material>Gazebo/Black</material>
        </gazebo>
        <transmission name="${prefix}_wheel_trans">
            <type>transmission_interface/SimpleTransmission</type>
            <joint name="${prefix}_wheel_joint">
                <hardwareInterface>hardware_interface/VelocityJointInterface</hardwareInterface>
            </joint>
            <actuator name="${prefix}_wheel_motor">
              <mechanicalReduction>34</mechanicalReduction>
               <hardwareInterface>hardware_interface/VelocityJointInterface</hardwareInterface>
            </actuator>
        </transmission>
            <gazebo reference="right_wheel">
        <mu1>1.0</mu1>
        <mu2>1.0</mu2>
        <kp>500000.0</kp>
        <kd>10.0</kd>
        <minDepth>0.001</minDepth>
        <maxVel>0.1</maxVel>
        <material>Gazebo/Black</material>
    </gazebo>
    </xacro:macro>
</robot>